Workbook

Sheet 2 months
B1: Member's Name: | C1: Sheila Mae Peñarubia | I1: Loan Amount: | J1: 50000 | L1: Member's Name: | M1: Sheila Mae Peñarubia | S1: Loan Amount: | T1: 50000
B2: Membership Number: | I2: Date | J2: 3/2/23 | L2: Membership Number: | S2: Date | T2: 3/2/23
B3: No. of Loan's Made: | I3: Interest Rate: | J3: 0.015 | L3: No. of Loan's Made: | P3: Interest Rate: | S3: Interest Rate: | T3: 0.015
B4: Mode of Payment: | I4: No. of months to Pay | J4: 2 | L4: Mode of Payment: | O4: No. of Months to Pay: | S4: No. of months to Pay | T4: 2
B5: Payment's Made | C5: Present Capital Loan | D5: Constant Payment Deducted to Capital Loan | E5: Interest Amount per Payment | F5: Amount to be Paid | G5: Paid Amount | H5: Date of Payment | I5: Receipt Number | J5: REMARKS | L5: Payment's Made | M5: Present Capital Loan | N5: Constant Payment Deducted to Capital Loan | O5: Interest Amount per Payment | P5: Amount to be Paid | Q5: Paid Amount | R5: Date of Payment | S5: Receipt Number | T5: REMARKS
B6: 1st Payment: | C6: =J1 -> 50000 | D6: =J1/J4 -> 25000 | E6: =(C6*0.015) -> 750 | F6: ='24 mos'!$C$255+E6 -> 100750 | L6: 1st Payment: | M6: =T1 -> 50000 | N6: =T1/T4 -> 25000 | O6: =(M6*0.015) -> 750 | P6: ='24 mos'!$C$255+O6 -> 100750
B7: 2nd Payment: | C7: 25000 | D7: 25000 | E7: =(C7*0.015) -> 375 | F7: ='24 mos'!$C$255+E7 -> 100375 | J7: Fully Paid | L7: 2nd Payment: | M7: 25000 | N7: 25000 | O7: =(M7*0.015) -> 375 | P7: ='24 mos'!$C$255+O7 -> 100375 | T7: Fully Paid
B10: Member's Name: | C10: Velasco, Virgilia | F10: (EMERGENCY LOAN) | I10: Loan Amount: | J10: 20000 | L10: Member's Name: | M10: Velasco, Virgilia | P10: (EMERGENCY LOAN) | S10: Loan Amount: | T10: 20000
B11: Membership Number: | I11: Date: | J11: 2/5/2025 | L11: Membership Number: | S11: Date: | T11: 2/5/2025
B12: No. of Loan's Made: | I12: Interest Rate: | J12: 0.015 | L12: No. of Loan's Made: | S12: Interest Rate: | T12: 0.015
B13: Mode of Payment: | I13: No. of Months to Pay: | J13: 2 | L13: Mode of Payment: | S13: No. of Months to Pay: | T13: 2
B14: Payment's Made | C14: Present Capital Loan | D14: Constant Payment Deducted to Capital Loan | E14: Interest Amount per Payment | F14: Amount to be Paid | G14: Paid Amount | H14: Date of Payment | I14: Receipt Number | J14: REMARKS | L14: Payment's Made | M14: Present Capital Loan | N14: Constant Payment Deducted to Capital Loan | O14: Interest Amount per Payment | P14: Amount to be Paid | Q14: Paid Amount | R14: Date of Payment | S14: Receipt Number | T14: REMARKS
B15: 1st Payment: | C15: =J10 -> 20000 | D15: =J10/J13 -> 10000 | E15: =(C15*0.015) -> 300 | F15: =SUM(D15:E15) -> 10300 | L15: 1st Payment: | M15: =T10 -> 20000 | N15: =T10/T13 -> 10000 | O15: =(M15*0.015) -> 300 | P15: =SUM(N15:O15) -> 10300
B16: 2nd Payment: | C16: 10000 | D16: 10000 | E16: =(C16*0.015) -> 150 | F16: =SUM(D16:E16) -> 10150 | J16: Fully Paid | L16: 2nd Payment: | M16: 10000 | N16: 10000 | O16: =(M16*0.015) -> 150 | P16: =SUM(N16:O16) -> 10150 | T16: Fully Paid
B19: Member's Name: | C19: Macabare, Ronnie | F19: Emergency Loan | H19: Loan Amount: | J19: 5000 | L19: Member's Name: | M19: Macabare, Ronnie | P19: Emergency Loan | R19: Loan Amount: | T19: 5000
B20: Membership Number: | I20: Date: | J20: 4/22/2024 | L20: Membership Number: | S20: Date: | T20: 4/22/2024
B21: No. of Loan's Made: | F21: Interest Rate: | J21: 0.015 | L21: No. of Loan's Made: | P21: Interest Rate: | T21: 0.015
B22: Mode of Payment: | E22: No. of Months to Pay: | J22: 2 | L22: Mode of Payment: | O22: No. of Months to Pay: | T22: 2
B23: Payment's Made | C23: Present Capital Loan | D23: Constant Payment Deducted to Capital Loan | E23: Interest Amount per Payment | F23: Amount to be Paid | G23: Paid Amount | H23: Date of Payment | I23: Receipt Number | J23: REMARKS | L23: Payment's Made | M23: Present Capital Loan | N23: Constant Payment Deducted to Capital Loan | O23: Interest Amount per Payment | P23: Amount to be Paid | Q23: Paid Amount | R23: Date of Payment | S23: Receipt Number | T23: REMARKS
B24: 1st Payment: | C24: =J19 -> 5000 | D24: =J19/J22 -> 2500 | E24: =(C24*0.015) -> 75 | F24: =SUM(D24:E24) -> 2575 | L24: 1st Payment: | M24: =T19 -> 5000 | N24: =T19/T22 -> 2500 | O24: =(M24*0.015) -> 75 | P24: =SUM(N24:O24) -> 2575
B25: 2nd Payment: | C25: 2500 | D25: 2500 | E25: =(C25*0.015) -> 37.5 | F25: =SUM(D25:E25) -> 2537.5 | J25: Fully Paid | L25: 2nd Payment: | M25: 2500 | N25: 2500 | O25: =(M25*0.015) -> 37.5 | P25: =SUM(N25:O25) -> 2537.5 | T25: Fully Paid

Sheet 1 month
B1: Member's Name: | C1: Virgilia Velasco | H1: Loan Amount: | J1: 20000 | L1: Member's Name: | M1: Virgilia Velasco | R1: Loan Amount: | T1: 20000
B2: Membership Number: | I2: Date: | J2: 5/3/23 | L2: Membership Number: | S2: Date: | T2: 5/3/23
B3: No. of Loan's Made: | F3: Interest Rate: | J3: 0.015 | L3: No. of Loan's Made: | P3: Interest Rate: | T3: 0.015
B4: Mode of Payment: | E4: No. of Months to Pay: | J4: 1 | L4: Mode of Payment: | O4: No. of Months to Pay: | T4: 1
B5: Payment's Made | C5: Present Capital Loan | D5: Constant Payment Deducted to Capital Loan | E5: Interest Amount per Payment | F5: Amount to be Paid | G5: Paid Amount | H5: Date of Payment | I5: Receipt Number | J5: REMARKS | L5: Payment's Made | M5: Present Capital Loan | N5: Constant Payment Deducted to Capital Loan | O5: Interest Amount per Payment | P5: Amount to be Paid | Q5: Paid Amount | R5: Date of Payment | S5: Receipt Number | T5: REMARKS
B6: 1st Payment: | C6: =J1 -> 20000 | D6: =J1/J4 -> 20000 | E6: =(C6*0.015) -> 300 | F6: ='24 mos'!$C$255+E6 -> 100300 | J6: Fully Paid | L6: 1st Payment: | M6: =T1 -> 20000 | N6: =T1/T4 -> 20000 | O6: =(M6*0.015) -> 300 | P6: ='24 mos'!$C$255+O6 -> 100300 | T6: Fully Paid
B9: Member's Name: | C9: Acala, Aimee | I9: Loan Amount: | J9: 10000 | L9: Member's Name: | M9: Acala, Aimee | S9: Loan Amount: | T9: 10000
B10: Membership Number: | I10: Date: | J10: 11/30/23 | L10: Membership Number: | S10: Date: | T10: 11/30/23
B11: No. of Loan's Made: | I11: Interest Rate: | J11: 0.015 | L11: No. of Loan's Made: | S11: Interest Rate: | T11: 0.015
B12: Mode of Payment: | I12: No. of Months to Pay: | J12: 1 | L12: Mode of Payment: | S12: No. of Months to Pay: | T12: 1
B13: Payment's Made | C13: Present Capital Loan | D13: Constant Payment Deducted to Capital Loan | E13: Interest Amount per Payment | F13: Amount to be Paid | G13: Paid Amount | H13: Date of Payment | I13: Receipt Number | J13: REMARKS | L13: Payment's Made | M13: Present Capital Loan | N13: Constant Payment Deducted to Capital Loan | O13: Interest Amount per Payment | P13: Amount to be Paid | Q13: Paid Amount | R13: Date of Payment | S13: Receipt Number | T13: REMARKS
B14: 1st Payment: | C14: =J9 -> 10000 | D14: =J9/J12 -> 10000 | E14: =(C14*0.015) -> 150 | F14: ='24 mos'!$C$255+E14 -> 100150 | J14: Fully Paid | L14: 1st Payment: | M14: =T9 -> 10000 | N14: =T9/T12 -> 10000 | O14: =(M14*0.015) -> 150 | P14: ='24 mos'!$C$255+O14 -> 100150 | T14: Fully Paid
B17: Member's Name: | I17: Loan Amount: | J17: 30000 | L17: Member's Name: | S17: Loan Amount: | T17: 30000
B18: Membership Number: | I18: Date: | L18: Membership Number: | S18: Date:
B19: No. of Loan's Made: | I19: Interest Rate: | J19: 0.015 | L19: No. of Loan's Made: | S19: Interest Rate: | T19: 0.015
B20: Mode of Payment: | I20: No. of Months to Pay: | J20: 1 | L20: Mode of Payment: | S20: No. of Months to Pay: | T20: 1
B21: Payment's Made | C21: Present Capital Loan | D21: Constant Payment Deducted to Capital Loan | E21: Interest Amount per Payment | F21: Amount to be Paid | G21: Paid Amount | H21: Date of Payment | I21: Receipt Number | J21: REMARKS | L21: Payment's Made | M21: Present Capital Loan | N21: Constant Payment Deducted to Capital Loan | O21: Interest Amount per Payment | P21: Amount to be Paid | Q21: Paid Amount | R21: Date of Payment | S21: Receipt Number | T21: REMARKS
B22: 1st Payment: | C22: =J17 -> 30000 | D22: =J17/J20 -> 30000 | E22: =(C22*0.015) -> 450 | F22: ='24 mos'!$C$255+E22 -> 100450 | J22: Fully Paid | L22: 1st Payment: | M22: =T17 -> 30000 | N22: =T17/T20 -> 30000 | O22: =(M22*0.015) -> 450 | P22: ='24 mos'!$C$255+O22 -> 100450 | T22: Fully Paid
B24: Member's Name: | C24: Tangtang, Neddie | F24: Emergency Loan | I24: Loan Amount: | J24: 5000 | L24: Member's Name: | M24: Tangtang, Neddie | P24: Emergency Loan | S24: Loan Amount: | T24: 5000
B25: Membership Number: | I25: Date: | J25: 6/21/2025 | L25: Membership Number: | S25: Date: | T25: 6/21/2025
B26: No. of Loan's Made: | I26: Interest Rate: | J26: 0.015 | L26: No. of Loan's Made: | S26: Interest Rate: | T26: 0.015
B27: Mode of Payment: | I27: No. of Months to Pay: | J27: 1 | L27: Mode of Payment: | S27: No. of Months to Pay: | T27: 1
B28: Payment's Made | C28: Present Capital Loan | D28: Constant Payment Deducted to Capital Loan | E28: Interest Amount per Payment | F28: Amount to be Paid | G28: Paid Amount | H28: Date of Payment | I28: Receipt Number | J28: REMARKS | L28: Payment's Made | M28: Present Capital Loan | N28: Constant Payment Deducted to Capital Loan | O28: Interest Amount per Payment | P28: Amount to be Paid | Q28: Paid Amount | R28: Date of Payment | S28: Receipt Number | T28: REMARKS
B29: 1st Payment: | C29: =J24 -> 5000 | D29: =J24/J27 -> 5000 | E29: =(C29*0.015) -> 75 | F29: =SUM(D29:E29) -> 5075 | J29: Fully Paid | L29: 1st Payment: | M29: =T24 -> 5000 | N29: =T24/T27 -> 5000 | O29: =(M29*0.015) -> 75 | P29: =SUM(N29:O29) -> 5075 | T29: Fully Paid

Sheet 18
B1: Member's Name: | C1: De Gracia, April | I1: Loan Amount: | J1: 50000 | L1: Member's Name: | M1: De Gracia, April | S1: Loan Amount: | T1: 50000
B2: Membership Number: | I2: Date: | J2: 6/13/2025 | L2: Membership Number: | S2: Date: | T2: 6/13/2025
B3: No. of Loan's Made: | I3: Interest Rate: | J3: 0.015 | L3: No. of Loan's Made: | S3: Interest Rate: | T3: 0.015
B4: Mode of Payment: | I4: No. of Months to Pay: | J4: 18 | L4: Mode of Payment: | S4: No. of Months to Pay: | T4: 18
B5: Payment's Made | C5: Present Capital Loan | D5: Constant Payment Deducted to Capital Loan | E5: Interest Amount per Payment | F5: Amount to be Paid | G5: Paid Amount | H5: Date of Payment | I5: Receipt Number | J5: REMARKS | L5: Payment's Made | M5: Present Capital Loan | N5: Constant Payment Deducted to Capital Loan | O5: Interest Amount per Payment | P5: Amount to be Paid | Q5: Paid Amount | R5: Date of Payment | S5: Receipt Number | T5: REMARKS
B6: 1st Payment: | C6: =J1 -> 50000 | D6: 2778 | E6: =(C6*0.015) -> 750 | F6: =SUM(D6:E6) -> 3528 | L6: 1st Payment: | M6: =T1 -> 50000 | N6: 2778 | O6: =(M6*0.015) -> 750 | P6: =SUM(N6:O6) -> 3528
B7: 2nd Payment: | C7: 47226 | D7: 2778 | E7: =(C7*0.015) -> 708.39 | F7: =SUM(D7:E7) -> 3486.39 | L7: 2nd Payment: | M7: 47226 | N7: 2778 | O7: =(M7*0.015) -> 708.39 | P7: =SUM(N7:O7) -> 3486.39
B8: 3rd Payment: | C8: 44448 | D8: 2778 | E8: =(C8*0.015) -> 666.72 | F8: =SUM(D8:E8) -> 3444.72 | L8: 3rd Payment: | M8: 44448 | N8: 2778 | O8: =(M8*0.015) -> 666.72 | P8: =SUM(N8:O8) -> 3444.72
B9: 4th Payment: | C9: 41670 | D9: 2778 | E9: =(C9*0.015) -> 625.05 | F9: =SUM(D9:E9) -> 3403.05 | L9: 4th Payment: | M9: 41670 | N9: 2778 | O9: =(M9*0.015) -> 625.05 | P9: =SUM(N9:O9) -> 3403.05
B10: 5th Payment: | C10: 38892 | D10: 2778 | E10: =(C10*0.015) -> 583.38 | F10: =SUM(D10:E10) -> 3361.38 | L10: 5th Payment: | M10: 38892 | N10: 2778 | O10: =(M10*0.015) -> 583.38 | P10: =SUM(N10:O10) -> 3361.38
B11: 6th Payment: | C11: 36114 | D11: 2778 | E11: =(C11*0.015) -> 541.71 | F11: =SUM(D11:E11) -> 3319.71 | L11: 6th Payment: | M11: 36114 | N11: 2778 | O11: =(M11*0.015) -> 541.71 | P11: =SUM(N11:O11) -> 3319.71
B12: 7th Payment: | C12: 33336 | D12: 2778 | E12: =(C12*0.015) -> 500.04 | F12: =SUM(D12:E12) -> 3278.04 | L12: 7th Payment: | M12: 33336 | N12: 2778 | O12: =(M12*0.015) -> 500.04 | P12: =SUM(N12:O12) -> 3278.04
B13: 8th Payment: | C13: 30558 | D13: 2778 | E13: =(C13*0.015) -> 458.37 | F13: =SUM(D13:E13) -> 3236.37 | L13: 8th Payment: | M13: 30558 | N13: 2778 | O13: =(M13*0.015) -> 458.37 | P13: =SUM(N13:O13) -> 3236.37
B14: 9th Payment: | C14: 27780 | D14: 2778 | E14: =(C14*0.015) -> 416.7 | F14: =SUM(D14:E14) -> 3194.7 | L14: 9th Payment: | M14: 27780 | N14: 2778 | O14: =(M14*0.015) -> 416.7 | P14: =SUM(N14:O14) -> 3194.7
B15: 10th Payment: | C15: 25002 | D15: 2778 | E15: =(C15*0.015) -> 375.03 | F15: =SUM(D15:E15) -> 3153.03 | L15: 10th Payment: | M15: 25002 | N15: 2778 | O15: =(M15*0.015) -> 375.03 | P15: =SUM(N15:O15) -> 3153.03
B16: 11th Payment: | C16: 22224 | D16: 2778 | E16: =(C16*0.015) -> 333.36 | F16: =SUM(D16:E16) -> 3111.36 | L16: 11th Payment: | M16: 22224 | N16: 2778 | O16: =(M16*0.015) -> 333.36 | P16: =SUM(N16:O16) -> 3111.36
B17: 12th Payment: | C17: 19446 | D17: 2778 | E17: =(C17*0.015) -> 291.69 | F17: =SUM(D17:E17) -> 3069.69 | L17: 12th Payment: | M17: 19446 | N17: 2778 | O17: =(M17*0.015) -> 291.69 | P17: =SUM(N17:O17) -> 3069.69
B18: 13th Payment: | C18: 16668 | D18: 2778 | E18: =(C18*0.015) -> 250.02 | F18: =SUM(D18:E18) -> 3028.02 | L18: 13th Payment: | M18: 16668 | N18: 2778 | O18: =(M18*0.015) -> 250.02 | P18: =SUM(N18:O18) -> 3028.02
... B22: 17th Payment: | C22: 5556 | D22: 2778 | E22: =(C22*0.015) -> 83.34 | F22: =SUM(D22:E22) -> 2861.34 | L22: 17th Payment: | M22: 5556 | N22: 2778 | O22: =(M22*0.015) -> 83.34 | P22: =SUM(N22:O22) -> 2861.34
B23: 18th Payment: | C23: 2778 | D23: 2778 | E23: =(C23*0.015) -> 41.67 | F23: =SUM(D23:E23) -> 2819.67 | J23: Fully paid | L23: 18th Payment: | M23: 2778 | N23: 2778 | O23: =(M23*0.015) -> 41.67 | P23: =SUM(N23:O23) -> 2819.67 | T23: Fully paid

Sheet 3 mos
B1: Member's Name: | C1: Macayan, Nenita | I1: Loan Amount: | J1: 50000 | L1: Member's Name: | M1: Macayan, Nenita | S1: Loan Amount: | T1: 50000
B2: Membership Number: | I2: Date: | J2: 7/14/2025 | L2: Membership Number: | S2: Date: | T2: 7/14/2025
B3: No. of Loan's Made: | I3: Interest Rate: | J3: 0.015 | L3: No. of Loan's Made: | S3: Interest Rate: | T3: 0.015
B4: Mode of Payment: | I4: No. of Months to Pay: | J4: 3 | L4: Mode of Payment: | S4: No. of Months to Pay: | T4: 3
B5: Payment's Made | C5: Present Capital Loan | D5: Constant Payment Deducted to Capital Loan | E5: Interest Amount per Payment | F5: Amount to be Paid | G5: Paid Amount | H5: Date of Payment | I5: Receipt Number | J5: REMARKS | L5: Payment's Made | M5: Present Capital Loan | N5: Constant Payment Deducted to Capital Loan | O5: Interest Amount per Payment | P5: Amount to be Paid | Q5: Paid Amount | R5: Date of Payment | S5: Receipt Number | T5: REMARKS
B6: 1st Payment: | C6: =J1 -> 50000 | D6: =J1/J4 -> 16666.667 | E6: =(C6*0.015) -> 750 | F6: =SUM(D6:E6) -> 17416.667 | L6: 1st Payment: | M6: =T1 -> 50000 | N6: =T1/T4 -> 16666.667 | O6: =(M6*0.015) -> 750 | P6: =SUM(N6:O6) -> 17416.667
B7: 2nd Payment: | C7: 33334 | D7: 16667 | E7: =(C7*0.015) -> 500.01 | F7: =SUM(D7:E7) -> 17167.01 | L7: 2nd Payment: | M7: 33334 | N7: 16667 | O7: =(M7*0.015) -> 500.01 | P7: =SUM(N7:O7) -> 17167.01
B8: 3rd Payment: | C8: 16667 | D8: 16667 | E8: =(C8*0.015) -> 250.005 | F8: =SUM(D8:E8) -> 16917.005 | J8: Fully Paid | L8: 3rd Payment: | M8: 16667 | N8: 16667 | O8: =(M8*0.015) -> 250.005 | P8: =SUM(N8:O8) -> 16917.005 | T8: Fully Paid
B11: Member's Name: | C11: Dela Peña, Benita | F11: (EMERGENCY LOAN) | I11: Loan Amount: | J11: 20000 | L11: Member's Name: | M11: Dela Peña, Benita | P11: (EMERGENCY LOAN) | S11: Loan Amount: | T11: 20000
B12: Membership Number: | I12: Date: | J12: 2/18/2025 | L12: Membership Number: | S12: Date: | T12: 2/18/2025
B13: No. of Loan's Made: | I13: Interest Rate: | J13: 0.015 | L13: No. of Loan's Made: | S13: Interest Rate: | T13: 0.015
B14: Mode of Payment: | I14: No. of Months to Pay: | J14: 3 | L14: Mode of Payment: | S14: No. of Months to Pay: | T14: 3
B15: Payment's Made | C15: Present Capital Loan | D15: Constant Payment Deducted to Capital Loan | E15: Interest Amount per Payment | F15: Amount to be Paid | G15: Paid Amount | H15: Date of Payment | I15: Receipt Number | J15: REMARKS | L15: Payment's Made | M15: Present Capital Loan | N15: Constant Payment Deducted to Capital Loan | O15: Interest Amount per Payment | P15: Amount to be Paid | Q15: Paid Amount | R15: Date of Payment | S15: Receipt Number | T15: REMARKS
B16: 1st Payment: | C16: =J11 -> 20000 | D16: =J11/J14 -> 6666.6667 | E16: =(C16*0.015) -> 300 | F16: =SUM(D16:E16) -> 6966.6667 | L16: 1st Payment: | M16: =T11 -> 20000 | N16: =T11/T14 -> 6666.6667 | O16: =(M16*0.015) -> 300 | P16: =SUM(N16:O16) -> 6966.6667
B17: 2nd Payment: | C17: 13334 | D17: 6667 | E17: =(C17*0.015) -> 200.01 | F17: =SUM(D17:E17) -> 6867.01 | L17: 2nd Payment: | M17: 13334 | N17: 6667 | O17: =(M17*0.015) -> 200.01 | P17: =SUM(N17:O17) -> 6867.01
B18: 3rd Payment: | C18: 6667 | D18: 6667 | E18: =(C18*0.015) -> 100.005 | F18: =SUM(D18:E18) -> 6767.005 | J18: Fully Paid | L18: 3rd Payment: | M18: 6667 | N18: 6667 | O18: =(M18*0.015) -> 100.005 | P18: =SUM(N18:O18) -> 6767.005 | T18: Fully Paid
B21: Member's Name: | C21: Mayores, Jenelyn | F21: Emergency Loan | H21: Loan Amount: | J21: 10000 | L21: Member's Name: | M21: Mayores, Jenelyn | P21: Emergency Loan | R21: Loan Amount: | T21: 10000
B22: Membership Number: | I22: Date: | J22: 7/29/2024 | L22: Membership Number: | S22: Date: | T22: 7/29/2024
B23: No. of Loan's Made: | F23: Interest Rate: | J23: 0.015 | L23: No. of Loan's Made: | P23: Interest Rate: | T23: 0.015
B24: Mode of Payment: | E24: No. of Months to Pay: | J24: 3 | L24: Mode of Payment: | O24: No. of Months to Pay: | T24: 3
B25: Payment's Made | C25: Present Capital Loan | D25: Constant Payment Deducted to Capital Loan | E25: Interest Amount per Payment | F25: Amount to be Paid | G25: Paid Amount | H25: Date of Payment | I25: Receipt Number | J25: REMARKS | L25: Payment's Made | M25: Present Capital Loan | N25: Constant Payment Deducted to Capital Loan | O25: Interest Amount per Payment | P25: Amount to be Paid | Q25: Paid Amount | R25: Date of Payment | S25: Receipt Number | T25: REMARKS
B26: 1st Payment: | C26: =J21 -> 10000 | D26: =J21/J24 -> 3333.3333 | E26: =(C26*0.015) -> 150 | F26: =SUM(D26:E26) -> 3483.3333 | L26: 1st Payment: | M26: =T21 -> 10000 | N26: =T21/T24 -> 3333.3333 | O26: =(M26*0.015) -> 150 | P26: =SUM(N26:O26) -> 3483.3333
B27: 2nd Payment: | C27: 6667 | D27: 3333 | E27: =(C27*0.015) -> 100.005 | F27: =SUM(D27:E27) -> 3433.005 | L27: 2nd Payment: | M27: 6667 | N27: 3333 | O27: =(M27*0.015) -> 100.005 | P27: =SUM(N27:O27) -> 3433.005
B28: 3rd Payment: | C28: 3333 | D28: 3333 | E28: =(C28*0.015) -> 49.995 | F28: =SUM(D28:E28) -> 3382.995 | J28: Fully Paid | L28: 3rd Payment: | M28: 3333 | N28: 3333 | O28: =(M28*0.015) -> 49.995 | P28: =SUM(N28:O28) -> 3382.995 | T28: Fully Paid
B31: Member's Name: | C31: Velasco, Virgilia | F31: Emergency Loan | H31: Loan Amount: | J31: 10000 | L31: Member's Name: | M31: Velasco, Virgilia | P31: Emergency Loan | R31: Loan Amount: | T31: 10000
B32: Membership Number: | I32: Date: | J32: 8/10/2024 | L32: Membership Number: | S32: Date: | T32: 8/10/2024
B33: No. of Loan's Made: | F33: Interest Rate: | J33: 0.015 | L33: No. of Loan's Made: | P33: Interest Rate: | T33: 0.015
B34: Mode of Payment: | E34: No. of Months to Pay: | J34: 3 | L34: Mode of Payment: | O34: No. of Months to Pay: | T34: 3
B35: Payment's Made | C35: Present Capital Loan | D35: Constant Payment Deducted to Capital Loan | E35: Interest Amount per Payment | F35: Amount to be Paid | G35: Paid Amount | H35: Date of Payment | I35: Receipt Number | J35: REMARKS | L35: Payment's Made | M35: Present Capital Loan | N35: Constant Payment Deducted to Capital Loan | O35: Interest Amount per Payment | P35: Amount to be Paid | Q35: Paid Amount | R35: Date of Payment | S35: Receipt Number | T35: REMARKS
B36: 1st Payment: | C36: =J31 -> 10000 | D36: =J31/J34 -> 3333.3333 | E36: =(C36*0.015) -> 150 | F36: =SUM(D36:E36) -> 3483.3333 | L36: 1st Payment: | M36: =T31 -> 10000 | N36: =T31/T34 -> 3333.3333 | O36: =(M36*0.015) -> 150 | P36: =SUM(N36:O36) -> 3483.3333
B37: 2nd Payment: | C37: 6666 | D37: 3333 | E37: =(C37*0.015) -> 99.99 | F37: =SUM(D37:E37) -> 3432.99 | L37: 2nd Payment: | M37: 6666 | N37: 3333 | O37: =(M37*0.015) -> 99.99 | P37: =SUM(N37:O37) -> 3432.99
B38: 3rd Payment: | C38: 3333 | D38: 3333 | E38: =(C38*0.015) -> 49.995 | F38: =SUM(D38:E38) -> 3382.995 | J38: Fully Paid | L38: 3rd Payment: | M38: 3333 | N38: 3333 | O38: =(M38*0.015) -> 49.995 | P38: =SUM(N38:O38) -> 3382.995 | T38: Fully Paid
B42: Member's Name: | C42: Crisostomo, Sophia | I42: Loan Amount: | J42: 100000
B43: Membership Number: | I43: Date:
B44: No. of Loan's Made: | I44: Interest Rate: | J44: 0.015
B45: Mode of Payment: | I45: No. of Months to Pay: | J45: 3
B46: Payment's Made | C46: Present Capital Loan | D46: Constant Payment Deducted to Capital Loan | E46: Interest Amount per Payment | F46: Amount to be Paid | G46: Paid Amount | H46: Date of Payment | I46: Receipt Number | J46: REMARKS
B47: 1st Payment: | C47: =J42 -> 100000 | D47: =J42/J45 -> 33333.333 | E47: =(C47*0.015) -> 1500 | F47: =SUM(D47:E47) -> 34833.333 | G47: 20000 | H47: 6/16/2025
B48: 2nd Payment: | C48: 66666 | D48: 33333 | E48: =(C48*0.015) -> 999.99 | F48: =SUM(D48:E48) -> 34332.99 | G48: 30000 | H48: 7/28/2025
B49: 3rd Payment: | C49: 33333 | D49: 33333 | E49: =(C49*0.015) -> 499.995 | F49: =SUM(D49:E49) -> 33832.995 | G49: 10000 | H49: 8/18/2025 | J49: Fully Paid
...

Sheet 9 mos
B1: Member's Name: | C1: Tuzon, Arlenita | I1: Loan Amount: | J1: 70000 | L1: Member's Name: | M1: Tuzon, Arlenita | S1: Loan Amount: | T1: 70000
B2: Membership Number: | I2: Date: | L2: Membership Number: | S2: Date:
B3: No. of Loan's Made: | I3: Interest Rate: | J3: 0.015 | L3: No. of Loan's Made: | S3: Interest Rate: | T3: 0.015
B4: Mode of Payment: | I4: No. of Months to Pay: | J4: 9 | L4: Mode of Payment: | S4: No. of Months to Pay: | T4: 9
B5: Payment's Made | C5: Present Capital Loan | D5: Constant Payment Deducted to Capital Loan | E5: Interest Amount per Payment | F5: Amount to be Paid | G5: Paid Amount | H5: Date of Payment | I5: Receipt Number | J5: REMARKS | L5: Payment's Made | M5: Present Capital Loan | N5: Constant Payment Deducted to Capital Loan | O5: Interest Amount per Payment | P5: Amount to be Paid | Q5: Paid Amount | R5: Date of Payment | S5: Receipt Number | T5: REMARKS
B6: 1st Payment: | C6: 70000 | D6: =J1/J4 -> 7777.7778 | E6: =(C6*0.015) -> 1050 | F6: =SUM(D6:E6) -> 8827.7778 | L6: 1st Payment: | M6: 70000 | N6: =T1/T4 -> 7777.7778 | O6: =(M6*0.015) -> 1050 | P6: =SUM(N6:O6) -> 8827.7778
B7: 2nd Payment: | C7: 62224 | D7: 7778 | E7: =(C7*0.015) -> 933.36 | F7: =SUM(D7:E7) -> 8711.36 | L7: 2nd Payment: | M7: 62224 | N7: 7778 | O7: =(M7*0.015) -> 933.36 | P7: =SUM(N7:O7) -> 8711.36
B8: 3rd Payment: | C8: 54446 | D8: 7778 | E8: =(C8*0.015) -> 816.69 | F8: =SUM(D8:E8) -> 8594.69 | L8: 3rd Payment: | M8: 54446 | N8: 7778 | O8: =(M8*0.015) -> 816.69 | P8: =SUM(N8:O8) -> 8594.69
B9: 4th Payment: | C9: 46668 | D9: 7778 | E9: =(C9*0.015) -> 700.02 | F9: =SUM(D9:E9) -> 8478.02 | L9: 4th Payment: | M9: 46668 | N9: 7778 | O9: =(M9*0.015) -> 700.02 | P9: =SUM(N9:O9) -> 8478.02
B10: 5th Payment: | C10: 38890 | D10: 7778 | E10: =(C10*0.015) -> 583.35 | F10: =SUM(D10:E10) -> 8361.35 | L10: 5th Payment: | M10: 38890 | N10: 7778 | O10: =(M10*0.015) -> 583.35 | P10: =SUM(N10:O10) -> 8361.35
B11: 6th Payment: | C11: 31112 | D11: 7778 | E11: =(C11*0.015) -> 466.68 | F11: =SUM(D11:E11) -> 8244.68 | L11: 6th Payment: | M11: 31112 | N11: 7778 | O11: =(M11*0.015) -> 466.68 | P11: =SUM(N11:O11) -> 8244.68
B12: 7th Payment: | C12: 23334 | D12: 7778 | E12: =(C12*0.015) -> 350.01 | F12: =SUM(D12:E12) -> 8128.01 | L12: 7th Payment: | M12: 23334 | N12: 7778 | O12: =(M12*0.015) -> 350.01 | P12: =SUM(N12:O12) -> 8128.01
B13: 8th Payment: | C13: 15556 | D13: 7778 | E13: =(C13*0.015) -> 233.34 | F13: =SUM(D13:E13) -> 8011.34 | L13: 8th Payment: | M13: 15556 | N13: 7778 | O13: =(M13*0.015) -> 233.34 | P13: =SUM(N13:O13) -> 8011.34
B14: 9th Payment: | C14: 7778 | D14: 7778 | E14: =(C14*0.015) -> 116.67 | F14: =SUM(D14:E14) -> 7894.67 | L14: 9th Payment: | M14: 7778 | N14: 7778 | O14: =(M14*0.015) -> 116.67 | P14: =SUM(N14:O14) -> 7894.67
B17: Member's Name: | C17: Vega, Divina | I17: Loan Amount: | J17: 100000 | L17: Member's Name: | M17: Vega, Divina | S17: Loan Amount: | T17: 100000
B18: Membership Number: | I18: Date: | J18: 7/29/2025 | L18: Membership Number: | S18: Date: | T18: 7/29/2025
B19: No. of Loan's Made: | I19: Interest Rate: | J19: 0.015 | L19: No. of Loan's Made: | S19: Interest Rate: | T19: 0.015
B20: Mode of Payment: | I20: No. of Months to Pay: | J20: 9 | L20: Mode of Payment: | S20: No. of Months to Pay: | T20: 9
B21: Payment's Made | C21: Present Capital Loan | D21: Constant Payment Deducted to Capital Loan | E21: Interest Amount per Payment | F21: Amount to be Paid | G21: Paid Amount | H21: Date of Payment | I21: Receipt Number | J21: REMARKS | L21: Payment's Made | M21: Present Capital Loan | N21: Constant Payment Deducted to Capital Loan | O21: Interest Amount per Payment | P21: Amount to be Paid | Q21: Paid Amount | R21: Date of Payment | S21: Receipt Number | T21: REMARKS
B22: 1st Payment: | C22: 100000 | D22: =J17/J20 -> 11111.111 | E22: =(C22*0.015) -> 1500 | F22: =SUM(D22:E22) -> 12611.111 | L22: 1st Payment: | M22: 100000 | N22: =T17/T20 -> 11111.111 | O22: =(M22*0.015) -> 1500 | P22: =SUM(N22:O22) -> 12611.111
B23: 2nd Payment: | C23: 88888 | D23: 11111 | E23: =(C23*0.015) -> 1333.32 | F23: =SUM(D23:E23) -> 12444.32 | L23: 2nd Payment: | M23: 88888 | N23: 11111 | O23: =(M23*0.015) -> 1333.32 | P23: =SUM(N23:O23) -> 12444.32
B24: 3rd Payment: | C24: 77777 | D24: 11111 | E24: =(C24*0.015) -> 1166.655 | F24: =SUM(D24:E24) -> 12277.655 | L24: 3rd Payment: | M24: 77777 | N24: 11111 | O24: =(M24*0.015) -> 1166.655 | P24: =SUM(N24:O24) -> 12277.655
B25: 4th Payment: | C25: 66666 | D25: 11111 | E25: =(C25*0.015) -> 999.99 | F25: =SUM(D25:E25) -> 12110.99 | L25: 4th Payment: | M25: 66666 | N25: 11111 | O25: =(M25*0.015) -> 999.99 | P25: =SUM(N25:O25) -> 12110.99
B26: 5th Payment: | C26: 55555 | D26: 11111 | E26: =(C26*0.015) -> 833.325 | F26: =SUM(D26:E26) -> 11944.325 | L26: 5th Payment: | M26: 55555 | N26: 11111 | O26: =(M26*0.015) -> 833.325 | P26: =SUM(N26:O26) -> 11944.325
B27: 6th Payment: | C27: 44444 | D27: 11111 | E27: =(C27*0.015) -> 666.66 | F27: =SUM(D27:E27) -> 11777.66 | L27: 6th Payment: | M27: 44444 | N27: 11111 | O27: =(M27*0.015) -> 666.66 | P27: =SUM(N27:O27) -> 11777.66
B28: 7th Payment: | C28: 33333 | D28: 11111 | E28: =(C28*0.015) -> 499.995 | F28: =SUM(D28:E28) -> 11610.995 | L28: 7th Payment: | M28: 33333 | N28: 11111 | O28: =(M28*0.015) -> 499.995 | P28: =SUM(N28:O28) -> 11610.995
B29: 8th Payment: | C29: 22222 | D29: 11111 | E29: =(C29*0.015) -> 333.33 | F29: =SUM(D29:E29) -> 11444.33 | L29: 8th Payment: | M29: 22222 | N29: 11111 | O29: =(M29*0.015) -> 333.33 | P29: =SUM(N29:O29) -> 11444.33
B30: 9th Payment: | C30: 11111 | D30: 11111 | E30: =(C30*0.015) -> 166.665 | F30: =SUM(D30:E30) -> 11277.665 | L30: 9th Payment: | M30: 11111 | N30: 11111 | O30: =(M30*0.015) -> 166.665 | P30: =SUM(N30:O30) -> 11277.665
F31: =SUM(F22:F30) -> 107499.05

Sheet 6 mos
B1: Member's Name: | C1: Yusingco, Marites | F1: Emergency Loan | H1: Loan Amount: | J1: 15000 | L1: Member's Name: | M1: Yusingco, Marites | P1: Emergency Loan | R1: Loan Amount: | T1: 15000
B2: Membership Number: | I2: Date: | J2: 3/24/2025 | L2: Membership Number: | S2: Date: | T2: 3/24/2025
B3: No. of Loan's Made: | F3: Interest Rate: | J3: 0.015 | L3: No. of Loan's Made: | P3: Interest Rate: | T3: 0.015
B4: Mode of Payment: | E4: No. of Months to Pay: | J4: 6 | L4: Mode of Payment: | O4: No. of Months to Pay: | T4: 6
B5: Payment's Made | C5: Present Capital Loan | D5: Constant Payment Deducted to Capital Loan | E5: Interest Amount per Payment | F5: Amount to be Paid | G5: Paid Amount | H5: Date of Payment | I5: Receipt Number | J5: REMARKS | L5: Payment's Made | M5: Present Capital Loan | N5: Constant Payment Deducted to Capital Loan | O5: Interest Amount per Payment | P5: Amount to be Paid | Q5: Paid Amount | R5: Date of Payment | S5: Receipt Number | T5: REMARKS
B6: 1st Payment: | C6: =J1 -> 15000 | D6: =J1/J4 -> 2500 | E6: =(C6*0.015) -> 225 | F6: =SUM(D6:E6) -> 2725 | L6: 1st Payment: | M6: =T1 -> 15000 | N6: =T1/T4 -> 2500 | O6: =(M6*0.015) -> 225 | P6: =SUM(N6:O6) -> 2725
B7: 2nd Payment: | C7: 12500 | D7: 2500 | E7: =(C7*0.015) -> 187.5 | F7: =SUM(D7:E7) -> 2687.5 | L7: 2nd Payment: | M7: 12500 | N7: 2500 | O7: =(M7*0.015) -> 187.5 | P7: =SUM(N7:O7) -> 2687.5
B8: 3rd Payment: | C8: 10000 | D8: 2500 | E8: =(C8*0.015) -> 150 | F8: =SUM(D8:E8) -> 2650 | L8: 3rd Payment: | M8: 10000 | N8: 2500 | O8: =(M8*0.015) -> 150 | P8: =SUM(N8:O8) -> 2650
B9: 4th Payment: | C9: 7500 | D9: 2500 | E9: =(C9*0.015) -> 112.5 | F9: =SUM(D9:E9) -> 2612.5 | L9: 4th Payment: | M9: 7500 | N9: 2500 | O9: =(M9*0.015) -> 112.5 | P9: =SUM(N9:O9) -> 2612.5
B10: 5th Payment: | C10: 5000 | D10: 2500 | E10: =(C10*0.015) -> 75 | F10: =SUM(D10:E10) -> 2575 | L10: 5th Payment: | M10: 5000 | N10: 2500 | O10: =(M10*0.015) -> 75 | P10: =SUM(N10:O10) -> 2575
B11: 6th Payment: | C11: 2500 | D11: 2500 | E11: =(C11*0.015) -> 37.5 | F11: =SUM(D11:E11) -> 2537.5 | J11: Fully Paid | L11: 6th Payment: | M11: 2500 | N11: 2500 | O11: =(M11*0.015) -> 37.5 | P11: =SUM(N11:O11) -> 2537.5 | T11: Fully Paid
B14: Member's Name: | C14: Batan, Hermelita | H14: Loan Amount: | J14: 200000 | L14: Member's Name: | M14: Batan, Hermelita | R14: Loan Amount: | T14: 200000
B15: Membership Number: | I15: Date: | J15: 4/18/2024 | L15: Membership Number: | S15: Date: | T15: 4/18/2024
B16: No. of Loan's Made: | F16: Interest Rate: | J16: 0.015 | L16: No. of Loan's Made: | P16: Interest Rate: | T16: 0.015
B17: Mode of Payment: | E17: No. of Months to Pay: | J17: 6 | L17: Mode of Payment: | O17: No. of Months to Pay: | T17: 6
B18: Payment's Made | C18: Present Capital Loan | D18: Constant Payment Deducted to Capital Loan | E18: Interest Amount per Payment | F18: Amount to be Paid | G18: Paid Amount | H18: Date of Payment | I18: Receipt Number | J18: REMARKS | L18: Payment's Made | M18: Present Capital Loan | N18: Constant Payment Deducted to Capital Loan | O18: Interest Amount per Payment | P18: Amount to be Paid | Q18: Paid Amount | R18: Date of Payment | S18: Receipt Number | T18: REMARKS
B19: 1st Payment: | C19: =J14 -> 200000 | D19: =J14/J17 -> 33333.333 | E19: =(C19*0.015) -> 3000 | F19: =SUM(D19:E19) -> 36333.333 | L19: 1st Payment: | M19: =T14 -> 200000 | N19: =T14/T17 -> 33333.333 | O19: =(M19*0.015) -> 3000 | P19: =SUM(N19:O19) -> 36333.333
B20: 2nd Payment: | C20: 166665 | D20: 33333 | E20: =(C20*0.015) -> 2499.975 | F20: =SUM(D20:E20) -> 35832.975 | L20: 2nd Payment: | M20: 166665 | N20: 33333 | O20: =(M20*0.015) -> 2499.975 | P20: =SUM(N20:O20) -> 35832.975
B21: 3rd Payment: | C21: 133332 | D21: 33333 | E21: =(C21*0.015) -> 1999.98 | F21: =SUM(D21:E21) -> 35332.98 | L21: 3rd Payment: | M21: 133332 | N21: 33333 | O21: =(M21*0.015) -> 1999.98 | P21: =SUM(N21:O21) -> 35332.98
B22: 4th Payment: | C22: 99999 | D22: 33333 | E22: =(C22*0.015) -> 1499.985 | F22: =SUM(D22:E22) -> 34832.985 | L22: 4th Payment: | M22: 99999 | N22: 33333 | O22: =(M22*0.015) -> 1499.985 | P22: =SUM(N22:O22) -> 34832.985
B23: 5th Payment: | C23: 66666 | D23: 33333 | E23: =(C23*0.015) -> 999.99 | F23: =SUM(D23:E23) -> 34332.99 | L23: 5th Payment: | M23: 66666 | N23: 33333 | O23: =(M23*0.015) -> 999.99 | P23: =SUM(N23:O23) -> 34332.99
B24: 6th Payment: | C24: 33333 | D24: 33333 | E24: =(C24*0.015) -> 499.995 | F24: =SUM(D24:E24) -> 33832.995 | J24: Fully Paid | L24: 6th Payment: | M24: 33333 | N24: 33333 | O24: =(M24*0.015) -> 499.995 | P24: =SUM(N24:O24) -> 33832.995 | T24: Fully Paid
B28: Member's Name: | C28: Malicdem, Elena | H28: Loan Amount: | J28: 20000 | L28: Member's Name: | M28: Malicdem, Elena | R28: Loan Amount: | T28: 20000
B29: Membership Number: | I29: Date: | J29: 4/4/2024 | L29: Membership Number: | S29: Date: | T29: 4/4/2024
B30: No. of Loan's Made: | F30: Interest Rate: | J30: 0.015 | L30: No. of Loan's Made: | P30: Interest Rate: | T30: 0.015
B31: Mode of Payment: | E31: No. of Months to Pay: | J31: 6 | L31: Mode of Payment: | O31: No. of Months to Pay: | T31: 6
B32: Payment's Made | C32: Present Capital Loan | D32: Constant Payment Deducted to Capital Loan | E32: Interest Amount per Payment | F32: Amount to be Paid | G32: Paid Amount | H32: Date of Payment | I32: Receipt Number | J32: REMARKS | L32: Payment's Made | M32: Present Capital Loan | N32: Constant Payment Deducted to Capital Loan | O32: Interest Amount per Payment | P32: Amount to be Paid | Q32: Paid Amount | R32: Date of Payment | S32: Receipt Number | T32: REMARKS
B33: 1st Payment: | C33: =J28 -> 20000 | D33: =J28/J31 -> 3333.3333 | E33: =(C33*0.015) -> 300 | F33: =SUM(D33:E33) -> 3633.3333 | L33: 1st Payment: | M33: =T28 -> 20000 | N33: =T28/T31 -> 3333.3333 | O33: =(M33*0.015) -> 300 | P33: =SUM(N33:O33) -> 3633.3333
B34: 2nd Payment: | C34: 16665 | D34: 3333 | E34: =(C34*0.015) -> 249.975 | F34: =SUM(D34:E34) -> 3582.975 | L34: 2nd Payment: | M34: 16665 | N34: 3333 | O34: =(M34*0.015) -> 249.975 | P34: =SUM(N34:O34) -> 3582.975
B35: 3rd Payment: | C35: 13332 | D35: 3333 | E35: =(C35*0.015) -> 199.98 | F35: =SUM(D35:E35) -> 3532.98 | L35: 3rd Payment: | M35: 13332 | N35: 3333 | O35: =(M35*0.015) -> 199.98 | P35: =SUM(N35:O35) -> 3532.98
B36: 4th Payment: | C36: 9999 | D36: 3333 | E36: =(C36*0.015) -> 149.985 | F36: =SUM(D36:E36) -> 3482.985 | L36: 4th Payment: | M36: 9999 | N36: 3333 | O36: =(M36*0.015) -> 149.985 | P36: =SUM(N36:O36) -> 3482.985
B37: 5th Payment: | C37: 6666 | D37: 3333 | E37: =(C37*0.015) -> 99.99 | F37: =SUM(D37:E37) -> 3432.99 | L37: 5th Payment: | M37: 6666 | N37: 3333 | O37: =(M37*0.015) -> 99.99 | P37: =SUM(N37:O37) -> 3432.99
B38: 6th Payment: | C38: 3333 | D38: 3333 | E38: =(C38*0.015) -> 49.995 | F38: =SUM(D38:E38) -> 3382.995 | J38: Fully Paid | L38: 6th Payment: | M38: 3333 | N38: 3333 | O38: =(M38*0.015) -> 49.995 | P38: =SUM(N38:O38) -> 3382.995 | T38: Fully Paid
B42: Member's Name: | C42: Buenaobra, Nordie | H42: Loan Amount: | J42: 10000 | L42: Member's Name: | M42: Buenaobra, Nordie | R42: Loan Amount: | T42: 10000
B43: Membership Number: | I43: Date: | J43: 5/21/2025 | L43: Membership Number: | S43: Date: | T43: 5/21/2025
B44: No. of Loan's Made: | F44: Interest Rate: | J44: 0.015 | L44: No. of Loan's Made: | P44: Interest Rate: | T44: 0.015
B45: Mode of Payment: | E45: No. of Months to Pay: | J45: 6 | L45: Mode of Payment: | O45: No. of Months to Pay: | T45: 6
B46: Payment's Made | C46: Present Capital Loan | D46: Constant Payment Deducted to Capital Loan | E46: Interest Amount per Payment | F46: Amount to be Paid | G46: Paid Amount | H46: Date of Payment | I46: Receipt Number | J46: REMARKS | L46: Payment's Made | M46: Present Capital Loan | N46: Constant Payment Deducted to Capital Loan | O46: Interest Amount per Payment | P46: Amount to be Paid | Q46: Paid Amount | R46: Date of Payment | S46: Receipt Number | T46: REMARKS
B47: 1st Payment: | C47: =J42 -> 10000 | D47: =J42/J45 -> 1666.6667 | E47: =(C47*0.015) -> 150 | F47: =SUM(D47:E47) -> 1816.6667 | L47: 1st Payment: | M47: =T42 -> 10000 | N47: =T42/T45 -> 1666.6667 | O47: =(M47*0.015) -> 150 | P47: =SUM(N47:O47) -> 1816.6667
B48: 2nd Payment: | C48: 8335 | D48: 1667 | E48: =(C48*0.015) -> 125.025 | F48: =SUM(D48:E48) -> 1792.025 | L48: 2nd Payment: | M48: 8335 | N48: 1667 | O48: =(M48*0.015) -> 125.025 | P48: =SUM(N48:O48) -> 1792.025
...

Sheet 8 mos
B1: Member's Name: | C1: Crisostomo, Sophia | I1: Loan Amount: | J1: 200000 | L1: Member's Name: | M1: Crisostomo, Sophia | S1: Loan Amount: | T1: 200000
B2: Membership Number: | I2: Date: | J2: 8/29/2025 | L2: Membership Number: | S2: Date: | T2: 8/29/2025
B3: No. of Loan's Made: | I3: Interest Rate: | J3: 0.015 | L3: No. of Loan's Made: | S3: Interest Rate: | T3: 0.015
B4: Mode of Payment: | I4: No. of Months to Pay: | J4: 8 | L4: Mode of Payment: | S4: No. of Months to Pay: | T4: 8
B5: Payment's Made | C5: Present Capital Loan | D5: Constant Payment Deducted to Capital Loan | E5: Interest Amount per Payment | F5: Amount to be Paid | G5: Paid Amount | H5: Date of Payment | I5: Receipt Number | J5: REMARKS | L5: Payment's Made | M5: Present Capital Loan | N5: Constant Payment Deducted to Capital Loan | O5: Interest Amount per Payment | P5: Amount to be Paid | Q5: Paid Amount | R5: Date of Payment | S5: Receipt Number | T5: REMARKS
B6: 1st Payment: | C6: 100000 | D6: =J1/J4 -> 25000 | E6: 3000 | F6: =SUM(D6:E6) -> 28000 | L6: 1st Payment: | M6: 100000 | N6: =T1/T4 -> 25000 | O6: 3000 | P6: =SUM(N6:O6) -> 28000
B7: 2nd Payment: | C7: 175000 | D7: 25000 | E7: =(C7*0.015) -> 2625 | F7: =SUM(D7:E7) -> 27625 | L7: 2nd Payment: | M7: 175000 | N7: 25000 | O7: =(M7*0.015) -> 2625 | P7: =SUM(N7:O7) -> 27625
B8: 3rd Payment: | C8: 150000 | D8: 25000 | E8: =(C8*0.015) -> 2250 | F8: =SUM(D8:E8) -> 27250 | L8: 3rd Payment: | M8: 150000 | N8: 25000 | O8: =(M8*0.015) -> 2250 | P8: =SUM(N8:O8) -> 27250
B9: 4th Payment: | C9: 125000 | D9: 25000 | E9: =(C9*0.015) -> 1875 | F9: =SUM(D9:E9) -> 26875 | L9: 4th Payment: | M9: 125000 | N9: 25000 | O9: =(M9*0.015) -> 1875 | P9: =SUM(N9:O9) -> 26875
B10: 5th Payment: | C10: 10000 | D10: 25000 | E10: 1500 | F10: =SUM(D10:E10) -> 26500 | L10: 5th Payment: | M10: 10000 | N10: 25000 | O10: 1500 | P10: =SUM(N10:O10) -> 26500
B11: 6th Payment: | C11: 75000 | D11: 25000 | E11: =(C11*0.015) -> 1125 | F11: =SUM(D11:E11) -> 26125 | L11: 6th Payment: | M11: 75000 | N11: 25000 | O11: =(M11*0.015) -> 1125 | P11: =SUM(N11:O11) -> 26125
B12: 7th Payment: | C12: 50000 | D12: 25000 | E12: =(C12*0.015) -> 750 | F12: =SUM(D12:E12) -> 25750 | L12: 7th Payment: | M12: 50000 | N12: 25000 | O12: =(M12*0.015) -> 750 | P12: =SUM(N12:O12) -> 25750
B13: 8th Payment: | C13: 25000 | D13: 25000 | E13: =(C13*0.015) -> 375 | F13: =SUM(D13:E13) -> 25375 | J13: Fully Paid | L13: 8th Payment: | M13: 25000 | N13: 25000 | O13: =(M13*0.015) -> 375 | P13: =SUM(N13:O13) -> 25375 | T13: Fully Paid

Sheet 15 mos
B1: Member's Name: | C1: Fontejon, Sandra | I1: Loan Amount: | J1: 40125 | L1: Member's Name: | M1: Fontejon, Sandra | S1: Loan Amount: | T1: 40125
B2: Membership Number: | I2: Date: | J2: 3/7/2025 | L2: Membership Number: | S2: Date: | T2: 3/7/2025
B3: No. of Loan's Made: | I3: Interest Rate: | J3: 0.015 | L3: No. of Loan's Made: | S3: Interest Rate: | T3: 0.015
B4: Mode of Payment: | I4: No. of Months to Pay: | J4: 15 | L4: Mode of Payment: | S4: No. of Months to Pay: | T4: 15
B5: Payment's Made | C5: Present Capital Loan | D5: Constant Payment Deducted to Capital Loan | E5: Interest Amount per Payment | F5: Amount to be Paid | G5: Paid Amount | H5: Date of Payment | I5: Receipt Number | J5: REMARKS | L5: Payment's Made | M5: Present Capital Loan | N5: Constant Payment Deducted to Capital Loan | O5: Interest Amount per Payment | P5: Amount to be Paid | Q5: Paid Amount | R5: Date of Payment | S5: Receipt Number | T5: REMARKS
B6: 1st Payment: | C6: =J1 -> 40125 | D6: =J1/J4 -> 2675 | E6: =(C6*0.015) -> 601.875 | F6: =SUM(D6:E6) -> 3276.875 | L6: 1st Payment: | M6: =T1 -> 40125 | N6: =T1/T4 -> 2675 | O6: =(M6*0.015) -> 601.875 | P6: =SUM(N6:O6) -> 3276.875
B7: 2nd Payment: | C7: 37450 | D7: 2675 | E7: =(C7*0.015) -> 561.75 | F7: =SUM(D7:E7) -> 3236.75 | L7: 2nd Payment: | M7: 37450 | N7: 2675 | O7: =(M7*0.015) -> 561.75 | P7: =SUM(N7:O7) -> 3236.75
B8: 3rd Payment: | C8: 34775 | D8: 2675 | E8: =(C8*0.015) -> 521.625 | F8: =SUM(D8:E8) -> 3196.625 | L8: 3rd Payment: | M8: 34775 | N8: 2675 | O8: =(M8*0.015) -> 521.625 | P8: =SUM(N8:O8) -> 3196.625
B9: 4th Payment: | C9: 32100 | D9: 2675 | E9: =(C9*0.015) -> 481.5 | F9: =SUM(D9:E9) -> 3156.5 | L9: 4th Payment: | M9: 32100 | N9: 2675 | O9: =(M9*0.015) -> 481.5 | P9: =SUM(N9:O9) -> 3156.5
B10: 5th Payment: | C10: 29425 | D10: 2675 | E10: =(C10*0.015) -> 441.375 | F10: =SUM(D10:E10) -> 3116.375 | L10: 5th Payment: | M10: 29425 | N10: 2675 | O10: =(M10*0.015) -> 441.375 | P10: =SUM(N10:O10) -> 3116.375
B11: 6th Payment: | C11: 26750 | D11: 2675 | E11: =(C11*0.015) -> 401.25 | F11: =SUM(D11:E11) -> 3076.25 | L11: 6th Payment: | M11: 26750 | N11: 2675 | O11: =(M11*0.015) -> 401.25 | P11: =SUM(N11:O11) -> 3076.25
B12: 7th Payment: | C12: 24075 | D12: 2675 | E12: =(C12*0.015) -> 361.125 | F12: =SUM(D12:E12) -> 3036.125 | L12: 7th Payment: | M12: 24075 | N12: 2675 | O12: =(M12*0.015) -> 361.125 | P12: =SUM(N12:O12) -> 3036.125
B13: 8th Payment: | C13: 21400 | D13: 2675 | E13: =(C13*0.015) -> 321 | F13: =SUM(D13:E13) -> 2996 | L13: 8th Payment: | M13: 21400 | N13: 2675 | O13: =(M13*0.015) -> 321 | P13: =SUM(N13:O13) -> 2996
B14: 9th Payment: | C14: 18725 | D14: 2675 | E14: =(C14*0.015) -> 280.875 | F14: =SUM(D14:E14) -> 2955.875 | L14: 9th Payment: | M14: 18725 | N14: 2675 | O14: =(M14*0.015) -> 280.875 | P14: =SUM(N14:O14) -> 2955.875
B15: 10th Payment: | C15: 16050 | D15: 2675 | E15: =(C15*0.015) -> 240.75 | F15: =SUM(D15:E15) -> 2915.75 | L15: 10th Payment: | M15: 16050 | N15: 2675 | O15: =(M15*0.015) -> 240.75 | P15: =SUM(N15:O15) -> 2915.75
B16: 11th Payment: | C16: 13375 | D16: 2675 | E16: =(C16*0.015) -> 200.625 | F16: =SUM(D16:E16) -> 2875.625 | L16: 11th Payment: | M16: 13375 | N16: 2675 | O16: =(M16*0.015) -> 200.625 | P16: =SUM(N16:O16) -> 2875.625
B17: 12th Payment: | C17: 10700 | D17: 2675 | E17: =(C17*0.015) -> 160.5 | F17: =SUM(D17:E17) -> 2835.5 | L17: 12th Payment: | M17: 10700 | N17: 2675 | O17: =(M17*0.015) -> 160.5 | P17: =SUM(N17:O17) -> 2835.5
B18: 13th Payment: | C18: 8025 | D18: 2675 | E18: =(C18*0.015) -> 120.375 | F18: =SUM(D18:E18) -> 2795.375 | L18: 13th Payment: | M18: 8025 | N18: 2675 | O18: =(M18*0.015) -> 120.375 | P18: =SUM(N18:O18) -> 2795.375
B19: 14th Payment: | C19: 5350 | D19: 2675 | E19: =(C19*0.015) -> 80.25 | F19: =SUM(D19:E19) -> 2755.25 | L19: 14th Payment: | M19: 5350 | N19: 2675 | O19: =(M19*0.015) -> 80.25 | P19: =SUM(N19:O19) -> 2755.25
B20: 15th Payment: | C20: 2675 | D20: 2675 | E20: =(C20*0.015) -> 40.125 | F20: =SUM(D20:E20) -> 2715.125 | J20: Fully Paid | L20: 15th Payment: | M20: 2675 | N20: 2675 | O20: =(M20*0.015) -> 40.125 | P20: =SUM(N20:O20) -> 2715.125 | T20: Fully Paid
B23: Member's Name: | C23: Moyo, Princess Warlene | I23: Loan Amount: | J23: 20000 | L23: Member's Name: | M23: Moyo, Princess Warlene | S23: Loan Amount: | T23: 20000
B24: Membership Number: | I24: Date: | J24: 6/20/2024 | L24: Membership Number: | S24: Date: | T24: 6/20/2024
B25: No. of Loan's Made: | I25: Interest Rate: | J25: 0.015 | L25: No. of Loan's Made: | S25: Interest Rate: | T25: 0.015
B26: Mode of Payment: | I26: No. of Months to Pay: | J26: 15 | L26: Mode of Payment: | S26: No. of Months to Pay: | T26: 15
B27: Payment's Made | C27: Present Capital Loan | D27: Constant Payment Deducted to Capital Loan | E27: Interest Amount per Payment | F27: Amount to be Paid | G27: Paid Amount | H27: Date of Payment | I27: Receipt Number | J27: REMARKS | L27: Payment's Made | M27: Present Capital Loan | N27: Constant Payment Deducted to Capital Loan | O27: Interest Amount per Payment | P27: Amount to be Paid | Q27: Paid Amount | R27: Date of Payment | S27: Receipt Number | T27: REMARKS
B28: 1st Payment: | C28: =J23 -> 20000 | D28: =J23/J26 -> 1333.3333 | E28: =(C28*0.015) -> 300 | F28: =SUM(D28:E28) -> 1633.3333 | L28: 1st Payment: | M28: =T23 -> 20000 | N28: =T23/T26 -> 1333.3333 | O28: =(M28*0.015) -> 300 | P28: =SUM(N28:O28) -> 1633.3333
B29: 2nd Payment: | C29: 18662 | D29: 1333 | E29: =(C29*0.015) -> 279.93 | F29: =SUM(D29:E29) -> 1612.93 | L29: 2nd Payment: | M29: 18662 | N29: 1333 | O29: =(M29*0.015) -> 279.93 | P29: =SUM(N29:O29) -> 1612.93
B30: 3rd Payment: | C30: 17329 | D30: 1333 | E30: =(C30*0.015) -> 259.935 | F30: =SUM(D30:E30) -> 1592.935 | L30: 3rd Payment: | M30: 17329 | N30: 1333 | O30: =(M30*0.015) -> 259.935 | P30: =SUM(N30:O30) -> 1592.935
B31: 4th Payment: | C31: 15996 | D31: 1333 | E31: =(C31*0.015) -> 239.94 | F31: =SUM(D31:E31) -> 1572.94 | L31: 4th Payment: | M31: 15996 | N31: 1333 | O31: =(M31*0.015) -> 239.94 | P31: =SUM(N31:O31) -> 1572.94
B32: 5th Payment: | C32: 14663 | D32: 1333 | E32: =(C32*0.015) -> 219.945 | F32: =SUM(D32:E32) -> 1552.945 | L32: 5th Payment: | M32: 14663 | N32: 1333 | O32: =(M32*0.015) -> 219.945 | P32: =SUM(N32:O32) -> 1552.945
B33: 6th Payment: | C33: 13330 | D33: 1333 | E33: =(C33*0.015) -> 199.95 | F33: =SUM(D33:E33) -> 1532.95 | L33: 6th Payment: | M33: 13330 | N33: 1333 | O33: =(M33*0.015) -> 199.95 | P33: =SUM(N33:O33) -> 1532.95
B34: 7th Payment: | C34: 11997 | D34: 1333 | E34: =(C34*0.015) -> 179.955 | F34: =SUM(D34:E34) -> 1512.955 | L34: 7th Payment: | M34: 11997 | N34: 1333 | O34: =(M34*0.015) -> 179.955 | P34: =SUM(N34:O34) -> 1512.955
B35: 8th Payment: | C35: 10664 | D35: 1333 | E35: =(C35*0.015) -> 159.96 | F35: =SUM(D35:E35) -> 1492.96 | L35: 8th Payment: | M35: 10664 | N35: 1333 | O35: =(M35*0.015) -> 159.96 | P35: =SUM(N35:O35) -> 1492.96
B36: 9th Payment: | C36: 9331 | D36: 1333 | E36: =(C36*0.015) -> 139.965 | F36: =SUM(D36:E36) -> 1472.965 | L36: 9th Payment: | M36: 9331 | N36: 1333 | O36: =(M36*0.015) -> 139.965 | P36: =SUM(N36:O36) -> 1472.965
B37: 10th Payment: | C37: 7998 | D37: 1333 | E37: =(C37*0.015) -> 119.97 | F37: =SUM(D37:E37) -> 1452.97 | L37: 10th Payment: | M37: 7998 | N37: 1333 | O37: =(M37*0.015) -> 119.97 | P37: =SUM(N37:O37) -> 1452.97
B38: 11th Payment: | C38: 6665 | D38: 1333 | E38: =(C38*0.015) -> 99.975 | F38: =SUM(D38:E38) -> 1432.975 | L38: 11th Payment: | M38: 6665 | N38: 1333 | O38: =(M38*0.015) -> 99.975 | P38: =SUM(N38:O38) -> 1432.975
B39: 12th Payment: | C39: 5332 | D39: 1333 | E39: =(C39*0.015) -> 79.98 | F39: =SUM(D39:E39) -> 1412.98 | L39: 12th Payment: | M39: 5332 | N39: 1333 | O39: =(M39*0.015) -> 79.98 | P39: =SUM(N39:O39) -> 1412.98
B40: 13th Payment: | C40: 3999 | D40: 1333 | E40: =(C40*0.015) -> 59.985 | F40: =SUM(D40:E40) -> 1392.985 | L40: 13th Payment: | M40: 3999 | N40: 1333 | O40: =(M40*0.015) -> 59.985 | P40: =SUM(N40:O40) -> 1392.985
B41: 14th Payment: | C41: 2666 | D41: 1333 | E41: =(C41*0.015) -> 39.99 | F41: =SUM(D41:E41) -> 1372.99 | L41: 14th Payment: | M41: 2666 | N41: 1333 | O41: =(M41*0.015) -> 39.99 | P41: =SUM(N41:O41) -> 1372.99
B42: 15th Payment: | C42: 1333 | D42: 1333 | E42: =(C42*0.015) -> 19.995 | F42: =SUM(D42:E42) -> 1352.995 | J42: Fully Paid | L42: 15th Payment: | M42: 1333 | N42: 1333 | O42: =(M42*0.015) -> 19.995 | P42: =SUM(N42:O42) -> 1352.995 | T42: Fully Paid
...

Sheet 20 mos
B1: Member's Name: | C1: Almorin, Santos | I1: Loan Amount: | J1: 30000 | L1: Member's Name: | M1: Almorin, Santos | S1: Loan Amount: | T1: 30000
B2: Membership Number: | I2: Date: | J2: 12/7/2024 | L2: Membership Number: | S2: Date: | T2: 12/7/2024
B3: No. of Loan's Made: | I3: Interest Rate: | J3: 0.015 | L3: No. of Loan's Made: | S3: Interest Rate: | T3: 0.015
B4: Mode of Payment: | I4: No. of Months to Pay: | J4: 20 | L4: Mode of Payment: | S4: No. of Months to Pay: | T4: 20
B5: Payment's Made | C5: Present Capital Loan | D5: Constant Payment Deducted to Capital Loan | E5: Interest Amount per Payment | F5: Amount to be Paid | G5: Paid Amount | H5: Date of Payment | I5: Receipt Number | J5: REMARKS | L5: Payment's Made | M5: Present Capital Loan | N5: Constant Payment Deducted to Capital Loan | O5: Interest Amount per Payment | P5: Amount to be Paid | Q5: Paid Amount | R5: Date of Payment | S5: Receipt Number | T5: REMARKS
B6: 1st Payment: | C6: 30000 | D6: =J1/J4 -> 1500 | E6: =(C6*0.015) -> 450 | F6: =SUM(D6:E6) -> 1950 | G6: 1950 | L6: 1st Payment: | M6: 30000 | N6: =T1/T4 -> 1500 | O6: =(M6*0.015) -> 450 | P6: =SUM(N6:O6) -> 1950
B7: 2nd Payment: | C7: 28500 | D7: 1500 | E7: =(C7*0.015) -> 427.5 | F7: =SUM(D7:E7) -> 1927.5 | G7: 1928 | L7: 2nd Payment: | M7: 28500 | N7: 1500 | O7: =(M7*0.015) -> 427.5 | P7: =SUM(N7:O7) -> 1927.5
B8: 3rd Payment: | C8: 27000 | D8: 1500 | E8: =(C8*0.015) -> 405 | F8: =SUM(D8:E8) -> 1905 | G8: 1905 | L8: 3rd Payment: | M8: 27000 | N8: 1500 | O8: =(M8*0.015) -> 405 | P8: =SUM(N8:O8) -> 1905
B9: 4th Payment: | C9: 25500 | D9: 1500 | E9: =(C9*0.015) -> 382.5 | F9: =SUM(D9:E9) -> 1882.5 | G9: 1883 | L9: 4th Payment: | M9: 25500 | N9: 1500 | O9: =(M9*0.015) -> 382.5 | P9: =SUM(N9:O9) -> 1882.5
B10: 5th Payment: | C10: 24000 | D10: 1500 | E10: =(C10*0.015) -> 360 | F10: =SUM(D10:E10) -> 1860 | G10: 3698 | L10: 5th Payment: | M10: 24000 | N10: 1500 | O10: =(M10*0.015) -> 360 | P10: =SUM(N10:O10) -> 1860
B11: 6th Payment: | C11: 22500 | D11: 1500 | E11: =(C11*0.015) -> 337.5 | F11: =SUM(D11:E11) -> 1837.5 | G11: 3608 | L11: 6th Payment: | M11: 22500 | N11: 1500 | O11: =(M11*0.015) -> 337.5 | P11: =SUM(N11:O11) -> 1837.5
B12: 7th Payment: | C12: 21000 | D12: 1500 | E12: =(C12*0.015) -> 315 | F12: =SUM(D12:E12) -> 1815 | G12: 3518 | L12: 7th Payment: | M12: 21000 | N12: 1500 | O12: =(M12*0.015) -> 315 | P12: =SUM(N12:O12) -> 1815
B13: 8th Payment: | C13: 19500 | D13: 1500 | E13: =(C13*0.015) -> 292.5 | F13: =SUM(D13:E13) -> 1792.5 | L13: 8th Payment: | M13: 19500 | N13: 1500 | O13: =(M13*0.015) -> 292.5 | P13: =SUM(N13:O13) -> 1792.5
B14: 9th Payment: | C14: 18000 | D14: 1500 | E14: =(C14*0.015) -> 270 | F14: =SUM(D14:E14) -> 1770 | L14: 9th Payment: | M14: 18000 | N14: 1500 | O14: =(M14*0.015) -> 270 | P14: =SUM(N14:O14) -> 1770
B15: 10th Payment: | C15: 16500 | D15: 1500 | E15: =(C15*0.015) -> 247.5 | F15: =SUM(D15:E15) -> 1747.5 | L15: 10th Payment: | M15: 16500 | N15: 1500 | O15: =(M15*0.015) -> 247.5 | P15: =SUM(N15:O15) -> 1747.5
B16: 11th Payment: | C16: 15000 | D16: 1500 | E16: =(C16*0.015) -> 225 | F16: =SUM(D16:E16) -> 1725 | L16: 11th Payment: | M16: 15000 | N16: 1500 | O16: =(M16*0.015) -> 225 | P16: =SUM(N16:O16) -> 1725
B17: 12th Payment: | C17: 13500 | D17: 1500 | E17: =(C17*0.015) -> 202.5 | F17: =SUM(D17:E17) -> 1702.5 | L17: 12th Payment: | M17: 13500 | N17: 1500 | O17: =(M17*0.015) -> 202.5 | P17: =SUM(N17:O17) -> 1702.5
B18: 13th Payment: | C18: 12000 | D18: 1500 | E18: =(C18*0.015) -> 180 | F18: =SUM(D18:E18) -> 1680 | L18: 13th Payment: | M18: 12000 | N18: 1500 | O18: =(M18*0.015) -> 180 | P18: =SUM(N18:O18) -> 1680
B19: 14th Payment: | C19: 10500 | D19: 1500 | E19: =(C19*0.015) -> 157.5 | F19: =SUM(D19:E19) -> 1657.5 | L19: 14th Payment: | M19: 10500 | N19: 1500 | O19: =(M19*0.015) -> 157.5 | P19: =SUM(N19:O19) -> 1657.5
B20: 15th Payment: | C20: 9000 | D20: 1500 | E20: =(C20*0.015) -> 135 | F20: =SUM(D20:E20) -> 1635 | L20: 15th Payment: | M20: 9000 | N20: 1500 | O20: =(M20*0.015) -> 135 | P20: =SUM(N20:O20) -> 1635
B21: 16th Payment: | C21: 7500 | D21: 1500 | E21: =(C21*0.015) -> 112.5 | F21: =SUM(D21:E21) -> 1612.5 | L21: 16th Payment: | M21: 7500 | N21: 1500 | O21: =(M21*0.015) -> 112.5 | P21: =SUM(N21:O21) -> 1612.5
B22: 17th Payment: | C22: 6000 | D22: 1500 | E22: =(C22*0.015) -> 90 | F22: =SUM(D22:E22) -> 1590 | L22: 17th Payment: | M22: 6000 | N22: 1500 | O22: =(M22*0.015) -> 90 | P22: =SUM(N22:O22) -> 1590
B23: 18th Payment: | C23: 4500 | D23: 1500 | E23: =(C23*0.015) -> 67.5 | F23: =SUM(D23:E23) -> 1567.5 | L23: 18th Payment: | M23: 4500 | N23: 1500 | O23: =(M23*0.015) -> 67.5 | P23: =SUM(N23:O23) -> 1567.5
B24: 19th Payment: | C24: 3000 | D24: 1500 | E24: =(C24*0.015) -> 45 | F24: =SUM(D24:E24) -> 1545 | L24: 19th Payment: | M24: 3000 | N24: 1500 | O24: =(M24*0.015) -> 45 | P24: =SUM(N24:O24) -> 1545
B25: 20th Payment: | C25: 1500 | D25: 1500 | E25: =(C25*0.015) -> 22.5 | F25: =SUM(D25:E25) -> 1522.5 | J25: Fully Paid | L25: 20th Payment: | M25: 1500 | N25: 1500 | O25: =(M25*0.015) -> 22.5 | P25: =SUM(N25:O25) -> 1522.5 | T25: Fully Paid
F26: =SUM(F6:F25) -> 34725 | G26: =SUM(G6:G25) -> 18490

Sheet 7 mos
B1: Member's Name: | C1: Anzures, Nancy | H1: Loan Amount: | J1: 7000 | L1: Member's Name: | M1: Anzures, Nancy | R1: Loan Amount: | T1: 7000
B2: Membership Number: | I2: Date: | J2: 2/1/23 | L2: Membership Number: | S2: Date: | T2: 2/1/23
B3: No. of Loan's Made: | F3: Interest Rate: | J3: 0.015 | L3: No. of Loan's Made: | P3: Interest Rate: | T3: 0.015
B4: Mode of Payment: | E4: No. of Months to Pay: | J4: 7 | L4: Mode of Payment: | O4: No. of Months to Pay: | T4: 7
B5: Payment's Made | C5: Present Capital Loan | D5: Constant Payment Deducted to Capital Loan | E5: Interest Amount per Payment | F5: Amount to be Paid | G5: Paid Amount | H5: Date of Payment | I5: Receipt Number | J5: REMARKS | L5: Payment's Made | M5: Present Capital Loan | N5: Constant Payment Deducted to Capital Loan | O5: Interest Amount per Payment | P5: Amount to be Paid | Q5: Paid Amount | R5: Date of Payment | S5: Receipt Number | T5: REMARKS
B6: 1st Payment: | C6: =J1 -> 7000 | D6: =J1/J4 -> 1000 | E6: =(C6*0.015) -> 105 | F6: =SUM(D6:E6) -> 1105 | L6: 1st Payment: | M6: =T1 -> 7000 | N6: =T1/T4 -> 1000 | O6: =(M6*0.015) -> 105 | P6: =SUM(N6:O6) -> 1105
B7: 2nd Payment: | C7: 6000 | D7: 1000 | E7: =(C7*0.015) -> 90 | F7: =SUM(D7:E7) -> 1090 | L7: 2nd Payment: | M7: 6000 | N7: 1000 | O7: =(M7*0.015) -> 90 | P7: =SUM(N7:O7) -> 1090
B8: 3rd Payment: | C8: 5000 | D8: 1000 | E8: =(C8*0.015) -> 75 | F8: =SUM(D8:E8) -> 1075 | L8: 3rd Payment: | M8: 5000 | N8: 1000 | O8: =(M8*0.015) -> 75 | P8: =SUM(N8:O8) -> 1075
B9: 4th Payment: | C9: 4000 | D9: 1000 | E9: =(C9*0.015) -> 60 | F9: =SUM(D9:E9) -> 1060 | L9: 4th Payment: | M9: 4000 | N9: 1000 | O9: =(M9*0.015) -> 60 | P9: =SUM(N9:O9) -> 1060
B10: 5th Payment: | C10: 3000 | D10: 1000 | E10: =(C10*0.015) -> 45 | F10: =SUM(D10:E10) -> 1045 | L10: 5th Payment: | M10: 3000 | N10: 1000 | O10: =(M10*0.015) -> 45 | P10: =SUM(N10:O10) -> 1045
B11: 6th Payment: | C11: 2000 | D11: 1000 | E11: =(C11*0.015) -> 30 | F11: =SUM(D11:E11) -> 1030 | L11: 6th Payment: | M11: 2000 | N11: 1000 | O11: =(M11*0.015) -> 30 | P11: =SUM(N11:O11) -> 1030
B12: 7th Payment: | C12: 1000 | D12: 1000 | E12: =(C12*0.015) -> 15 | F12: =SUM(D12:E12) -> 1015 | J12: Fully Paid | L12: 7th Payment: | M12: 1000 | N12: 1000 | O12: =(M12*0.015) -> 15 | P12: =SUM(N12:O12) -> 1015 | T12: Fully Paid

Sheet 5 mos
B1: Member's Name: | C1: Crisostomo, Sofia | H1: Loan Amount: | J1: 100000 | L1: Member's Name: | M1: Crisostomo, Sofia | R1: Loan Amount: | T1: 100000
B2: Membership Number: | I2: Date: | J2: 3/25/2025 | L2: Membership Number: | S2: Date: | T2: 3/25/2025
B3: No. of Loan's Made: | F3: Interest Rate: | J3: 0.015 | L3: No. of Loan's Made: | P3: Interest Rate: | T3: 0.015
B4: Mode of Payment: | E4: No. of Months to Pay: | J4: 5 | L4: Mode of Payment: | O4: No. of Months to Pay: | T4: 5
B5: Payment's Made | C5: Present Capital Loan | D5: Constant Payment Deducted to Capital Loan | E5: Interest Amount per Payment | F5: Amount to be Paid | G5: Paid Amount | H5: Date of Payment | I5: Receipt Number | J5: REMARKS | L5: Payment's Made | M5: Present Capital Loan | N5: Constant Payment Deducted to Capital Loan | O5: Interest Amount per Payment | P5: Amount to be Paid | Q5: Paid Amount | R5: Date of Payment | S5: Receipt Number | T5: REMARKS
B6: 1st Payment: | C6: =J1 -> 100000 | D6: =J1/J4 -> 20000 | E6: =(C6*0.015) -> 1500 | F6: =SUM(D6:E6) -> 21500 | L6: 1st Payment: | M6: =T1 -> 100000 | N6: =T1/T4 -> 20000 | O6: =(M6*0.015) -> 1500 | P6: =SUM(N6:O6) -> 21500
B7: 2nd Payment: | C7: 80000 | D7: 20000 | E7: =(C7*0.015) -> 1200 | F7: =SUM(D7:E7) -> 21200 | L7: 2nd Payment: | M7: 80000 | N7: 20000 | O7: =(M7*0.015) -> 1200 | P7: =SUM(N7:O7) -> 21200
B8: 3rd Payment: | C8: 60000 | D8: 20000 | E8: =(C8*0.015) -> 900 | F8: =SUM(D8:E8) -> 20900 | L8: 3rd Payment: | M8: 60000 | N8: 20000 | O8: =(M8*0.015) -> 900 | P8: =SUM(N8:O8) -> 20900
B9: 4th Payment: | C9: 40000 | D9: 20000 | E9: =(C9*0.015) -> 600 | F9: =SUM(D9:E9) -> 20600 | L9: 4th Payment: | M9: 40000 | N9: 20000 | O9: =(M9*0.015) -> 600 | P9: =SUM(N9:O9) -> 20600
B10: 5th Payment: | C10: 20000 | D10: 20000 | E10: =(C10*0.015) -> 300 | F10: =SUM(D10:E10) -> 20300 | J10: Fully Paid | L10: 5th Payment: | M10: 20000 | N10: 20000 | O10: =(M10*0.015) -> 300 | P10: =SUM(N10:O10) -> 20300 | T10: Fully Paid
B13: Member's Name: | C13: Velasco, Virgilia | F13: Emergency Loan | H13: Loan Amount: | J13: 10000 | L13: Member's Name: | M13: Velasco, Virgilia | P13: Emergency Loan | R13: Loan Amount: | T13: 10000
B14: Membership Number: | I14: Date: | J14: 2/12/2024 | L14: Membership Number: | S14: Date: | T14: 2/12/2024
B15: No. of Loan's Made: | F15: Interest Rate: | J15: 0.015 | L15: No. of Loan's Made: | P15: Interest Rate: | T15: 0.015
B16: Mode of Payment: | E16: No. of Months to Pay: | J16: 5 | L16: Mode of Payment: | O16: No. of Months to Pay: | T16: 5
B17: Payment's Made | C17: Present Capital Loan | D17: Constant Payment Deducted to Capital Loan | E17: Interest Amount per Payment | F17: Amount to be Paid | G17: Paid Amount | H17: Date of Payment | I17: Receipt Number | J17: REMARKS | L17: Payment's Made | M17: Present Capital Loan | N17: Constant Payment Deducted to Capital Loan | O17: Interest Amount per Payment | P17: Amount to be Paid | Q17: Paid Amount | R17: Date of Payment | S17: Receipt Number | T17: REMARKS
B18: 1st Payment: | C18: =J13 -> 10000 | D18: =J13/J16 -> 2000 | E18: =(C18*0.015) -> 150 | F18: =SUM(D18:E18) -> 2150 | L18: 1st Payment: | M18: =T13 -> 10000 | N18: =T13/T16 -> 2000 | O18: =(M18*0.015) -> 150 | P18: =SUM(N18:O18) -> 2150
B19: 2nd Payment: | C19: 8000 | D19: 2000 | E19: =(C19*0.015) -> 120 | F19: =SUM(D19:E19) -> 2120 | L19: 2nd Payment: | M19: 8000 | N19: 2000 | O19: =(M19*0.015) -> 120 | P19: =SUM(N19:O19) -> 2120
B20: 3rd Payment: | C20: 6000 | D20: 2000 | E20: =(C20*0.015) -> 90 | F20: =SUM(D20:E20) -> 2090 | L20: 3rd Payment: | M20: 6000 | N20: 2000 | O20: =(M20*0.015) -> 90 | P20: =SUM(N20:O20) -> 2090
B21: 4th Payment: | C21: 4000 | D21: 2000 | E21: =(C21*0.015) -> 60 | F21: =SUM(D21:E21) -> 2060 | L21: 4th Payment: | M21: 4000 | N21: 2000 | O21: =(M21*0.015) -> 60 | P21: =SUM(N21:O21) -> 2060
B22: 5th Payment: | C22: 2000 | D22: 2000 | E22: =(C22*0.015) -> 30 | F22: =SUM(D22:E22) -> 2030 | J22: Fully Paid | L22: 5th Payment: | M22: 2000 | N22: 2000 | O22: =(M22*0.015) -> 30 | P22: =SUM(N22:O22) -> 2030 | T22: Fully Paid
B25: Member's Name: | C25: Duran, Rosana | H25: Loan Amount: | J25: 10000 | L25: Member's Name: | M25: Duran, Rosana | R25: Loan Amount: | T25: 10000
B26: Membership Number: | I26: Date: | J26: 7/4/2025 | L26: Membership Number: | S26: Date: | T26: 7/4/2025
B27: No. of Loan's Made: | F27: Interest Rate: | J27: 0.015 | L27: No. of Loan's Made: | P27: Interest Rate: | T27: 0.015
B28: Mode of Payment: | E28: No. of Months to Pay: | J28: 5 | L28: Mode of Payment: | O28: No. of Months to Pay: | T28: 5
B29: Payment's Made | C29: Present Capital Loan | D29: Constant Payment Deducted to Capital Loan | E29: Interest Amount per Payment | F29: Amount to be Paid | G29: Paid Amount | H29: Date of Payment | I29: Receipt Number | J29: REMARKS | L29: Payment's Made | M29: Present Capital Loan | N29: Constant Payment Deducted to Capital Loan | O29: Interest Amount per Payment | P29: Amount to be Paid | Q29: Paid Amount | R29: Date of Payment | S29: Receipt Number | T29: REMARKS
B30: 1st Payment: | C30: =J25 -> 10000 | D30: =J25/J28 -> 2000 | E30: =(C30*0.015) -> 150 | F30: =SUM(D30:E30) -> 2150 | L30: 1st Payment: | M30: =T25 -> 10000 | N30: =T25/T28 -> 2000 | O30: =(M30*0.015) -> 150 | P30: =SUM(N30:O30) -> 2150
B31: 2nd Payment: | C31: 8000 | D31: 2000 | E31: =(C31*0.015) -> 120 | F31: =SUM(D31:E31) -> 2120 | L31: 2nd Payment: | M31: 8000 | N31: 2000 | O31: =(M31*0.015) -> 120 | P31: =SUM(N31:O31) -> 2120
B32: 3rd Payment: | C32: 6000 | D32: 2000 | E32: =(C32*0.015) -> 90 | F32: =SUM(D32:E32) -> 2090 | L32: 3rd Payment: | M32: 6000 | N32: 2000 | O32: =(M32*0.015) -> 90 | P32: =SUM(N32:O32) -> 2090
B33: 4th Payment: | C33: 4000 | D33: 2000 | E33: =(C33*0.015) -> 60 | F33: =SUM(D33:E33) -> 2060 | L33: 4th Payment: | M33: 4000 | N33: 2000 | O33: =(M33*0.015) -> 60 | P33: =SUM(N33:O33) -> 2060
